<?xml version="1.0" encoding="utf-8"?>
<!-- This URDF was automatically created by SolidWorks to URDF Exporter! Originally created by Stephen Brawner (brawner@gmail.com) 
     Commit Version: 1.6.0-4-g7f85cfe  Build Version: 1.6.7995.38578
     For more information, please see http://wiki.ros.org/sw_urdf_exporter -->
<robot
  name="hand">
  <link
    name="palm">
    <inertial>
      <origin
        xyz="-0.0013307 0.0010114 0.062993"
        rpy="0 0 0" />
      <mass
        value="0.094529" />
      <inertia
        ixx="0.0001357"
        ixy="1.4777E-06"
        ixz="3.568E-07"
        iyy="0.00017087"
        iyz="1.1375E-06"
        izz="6.3659E-05" />
    </inertial>
    <visual>
      <origin
        xyz="0 0 0"
        rpy="0 0 0" />
      <geometry>
        <mesh
          filename="package://hand/meshes/palm.STL" />
      </geometry>
      <material
        name="">
        <color
          rgba="0.79216 0.81961 0.93333 1" />
      </material>
    </visual>
    <collision>
      <origin
        xyz="0 0 0"
        rpy="0 0 0" />
      <geometry>
        <mesh
          filename="package://hand/meshes/palm.STL" />
      </geometry>
    </collision>
  </link>
  <link
    name="thumb1">
    <inertial>
      <origin
        xyz="0.0040775 5.1448E-06 -8.4377E-06"
        rpy="0 0 0" />
      <mass
        value="0.00094362" />
      <inertia
        ixx="1.9603E-08"
        ixy="9.8917E-13"
        ixz="6.2515E-11"
        iyy="4.104E-08"
        iyz="-4.0962E-14"
        izz="2.901E-08" />
    </inertial>
    <visual>
      <origin
        xyz="0 0 0"
        rpy="0 0 0" />
      <geometry>
        <mesh
          filename="package://hand/meshes/thumb1.STL" />
      </geometry>
      <material
        name="">
        <color
          rgba="0.79216 0.81961 0.93333 1" />
      </material>
    </visual>
    <collision>
      <origin
        xyz="0 0 0"
        rpy="0 0 0" />
      <geometry>
        <mesh
          filename="package://hand/meshes/thumb1.STL" />
      </geometry>
    </collision>
  </link>
  <joint
    name="palm_thumb1"
    type="revolute">
    <origin
      xyz="0.021198 0.01582 0.053"
      rpy="0 0 0" />
    <parent
      link="palm" />
    <child
      link="thumb1" />
    <axis
      xyz="0 0 1" />
    <limit
      lower="-1.57"
      upper="1.57"
      effort="0"
      velocity="0" />
  </joint>
  <link
    name="thumb2">
    <inertial>
      <origin
        xyz="0.023578 -0.00022362 7.7799E-07"
        rpy="0 0 0" />
      <mass
        value="0.0094731" />
      <inertia
        ixx="9.8539E-07"
        ixy="1.3505E-07"
        ixz="1.9088E-10"
        iyy="2.3115E-06"
        iyz="1.1807E-10"
        izz="2.7955E-06" />
    </inertial>
    <visual>
      <origin
        xyz="0 0 0"
        rpy="0 0 0" />
      <geometry>
        <mesh
          filename="package://hand/meshes/thumb2.STL" />
      </geometry>
      <material
        name="">
        <color
          rgba="0.79216 0.81961 0.93333 1" />
      </material>
    </visual>
    <collision>
      <origin
        xyz="0 0 0"
        rpy="0 0 0" />
      <geometry>
        <mesh
          filename="package://hand/meshes/thumb2.STL" />
      </geometry>
    </collision>
  </link>
  <joint
    name="thumb_12"
    type="revolute">
    <origin
      xyz="0.011644 0 -5.656E-05"
      rpy="-1.5708 0 0" />
    <parent
      link="thumb1" />
    <child
      link="thumb2" />
    <axis
      xyz="0 0 -1" />
    <limit
      lower="-1.57"
      upper="1.57"
      effort="0"
      velocity="0" />
  </joint>
  <link
    name="thumb3">
    <inertial>
      <origin
        xyz="0.013839 0.00085022 2.7025E-06"
        rpy="0 0 0" />
      <mass
        value="0.006391" />
      <inertia
        ixx="4.7292E-07"
        ixy="-9.0106E-09"
        ixz="8.9883E-11"
        iyy="6.5656E-07"
        iyz="-2.3775E-10"
        izz="8.1196E-07" />
    </inertial>
    <visual>
      <origin
        xyz="0 0 0"
        rpy="0 0 0" />
      <geometry>
        <mesh
          filename="package://hand/meshes/thumb3.STL" />
      </geometry>
      <material
        name="">
        <color
          rgba="0.79216 0.81961 0.93333 1" />
      </material>
    </visual>
    <collision>
      <origin
        xyz="0 0 0"
        rpy="0 0 0" />
      <geometry>
        <mesh
          filename="package://hand/meshes/thumb3.STL" />
      </geometry>
    </collision>
  </link>
  <joint
    name="thumb_23"
    type="revolute">
    <origin
      xyz="0.043954 0 0"
      rpy="0 0 0" />
    <parent
      link="thumb2" />
    <child
      link="thumb3" />
    <axis
      xyz="0 0 -1" />
    <limit
      lower="-1.57"
      upper="1.57"
      effort="0"
      velocity="0" />
  </joint>
  <link
    name="thumb4">
    <inertial>
      <origin
        xyz="0.013621 0.00047042 7.267E-08"
        rpy="0 0 0" />
      <mass
        value="0.0039861" />
      <inertia
        ixx="1.0034E-07"
        ixy="1.8877E-08"
        ixz="1.7483E-12"
        iyy="2.8593E-07"
        iyz="-2.4367E-12"
        izz="2.98E-07" />
    </inertial>
    <visual>
      <origin
        xyz="0 0 0"
        rpy="0 0 0" />
      <geometry>
        <mesh
          filename="package://hand/meshes/thumb4.STL" />
      </geometry>
      <material
        name="">
        <color
          rgba="0.79216 0.81961 0.93333 1" />
      </material>
    </visual>
    <collision>
      <origin
        xyz="0 0 0"
        rpy="0 0 0" />
      <geometry>
        <mesh
          filename="package://hand/meshes/thumb4.STL" />
      </geometry>
    </collision>
  </link>
  <joint
    name="thumb_34"
    type="revolute">
    <origin
      xyz="0.029871 0 0"
      rpy="0 0 0" />
    <parent
      link="thumb3" />
    <child
      link="thumb4" />
    <axis
      xyz="0 0 -1" />
    <limit
      lower="-1.57"
      upper="1.57"
      effort="0"
      velocity="0" />
  </joint>
  <link
    name="index1">
    <inertial>
      <origin
        xyz="0.01519 -0.0017071 -1.0062E-06"
        rpy="0 0 0" />
      <mass
        value="0.0052421" />
      <inertia
        ixx="2.1523E-07"
        ixy="8.2486E-09"
        ixz="4.1897E-12"
        iyy="8.1651E-07"
        iyz="-4.8384E-11"
        izz="8.927E-07" />
    </inertial>
    <visual>
      <origin
        xyz="0 0 0"
        rpy="0 0 0" />
      <geometry>
        <mesh
          filename="package://hand/meshes/index1.STL" />
      </geometry>
      <material
        name="">
        <color
          rgba="0.79216 0.81961 0.93333 1" />
      </material>
    </visual>
    <collision>
      <origin
        xyz="0 0 0"
        rpy="0 0 0" />
      <geometry>
        <mesh
          filename="package://hand/meshes/index1.STL" />
      </geometry>
    </collision>
  </link>
  <joint
    name="palm_index1"
    type="revolute">
    <origin
      xyz="0.026145 -0.0020908 0.12443"
      rpy="0 -1.5359 0" />
    <parent
      link="palm" />
    <child
      link="index1" />
    <axis
      xyz="0 0.00060917 1" />
    <limit
      lower="-1.57"
      upper="1.57"
      effort="0"
      velocity="0" />
  </joint>
  <link
    name="index2">
    <inertial>
      <origin
        xyz="0.020114 -0.0023316 -3.1197E-06"
        rpy="0 0 0" />
      <mass
        value="0.0041819" />
      <inertia
        ixx="8.3265E-08"
        ixy="-4.8742E-08"
        ixz="-1.3487E-10"
        iyy="6.592E-07"
        iyz="-6.6485E-11"
        izz="6.6964E-07" />
    </inertial>
    <visual>
      <origin
        xyz="0 0 0"
        rpy="0 0 0" />
      <geometry>
        <mesh
          filename="package://hand/meshes/index2.STL" />
      </geometry>
      <material
        name="">
        <color
          rgba="0.79216 0.81961 0.93333 1" />
      </material>
    </visual>
    <collision>
      <origin
        xyz="0 0 0"
        rpy="0 0 0" />
      <geometry>
        <mesh
          filename="package://hand/meshes/index2.STL" />
      </geometry>
    </collision>
  </link>
  <joint
    name="index_12"
    type="revolute">
    <origin
      xyz="0.036321 0 0"
      rpy="0 0 0" />
    <parent
      link="index1" />
    <child
      link="index2" />
    <axis
      xyz="0 0.00060917 1" />
    <limit
      lower="-1.57"
      upper="1.57"
      effort="0"
      velocity="0" />
  </joint>
  <link
    name="middle1">
    <inertial>
      <origin
        xyz="0.014781 -0.0016035 1.0345E-07"
        rpy="0 0 0" />
      <mass
        value="0.0051082" />
      <inertia
        ixx="2.1368E-07"
        ixy="2.8666E-08"
        ixz="-9.5921E-12"
        iyy="7.7861E-07"
        iyz="-2.3932E-12"
        izz="8.5557E-07" />
    </inertial>
    <visual>
      <origin
        xyz="0 0 0"
        rpy="0 0 0" />
      <geometry>
        <mesh
          filename="package://hand/meshes/middle1.STL" />
      </geometry>
      <material
        name="">
        <color
          rgba="0.79216 0.81961 0.93333 1" />
      </material>
    </visual>
    <collision>
      <origin
        xyz="0 0 0"
        rpy="0 0 0" />
      <geometry>
        <mesh
          filename="package://hand/meshes/middle1.STL" />
      </geometry>
    </collision>
  </link>
  <joint
    name="palm_middle1"
    type="revolute">
    <origin
      xyz="0.0069479 -0.0020971 0.12479"
      rpy="0 -1.5708 0" />
    <parent
      link="palm" />
    <child
      link="middle1" />
    <axis
      xyz="0 0 1" />
    <limit
      lower="-1.57"
      upper="1.57"
      effort="0"
      velocity="0" />
  </joint>
  <link
    name="middle2">
    <inertial>
      <origin
        xyz="0.020341 -0.0024484 4.4802E-05"
        rpy="0 0 0" />
      <mass
        value="0.0042456" />
      <inertia
        ixx="8.5355E-08"
        ixy="-5.2791E-08"
        ixz="-4.1309E-10"
        iyy="6.8199E-07"
        iyz="-1.0381E-11"
        izz="6.9313E-07" />
    </inertial>
    <visual>
      <origin
        xyz="0 0 0"
        rpy="0 0 0" />
      <geometry>
        <mesh
          filename="package://hand/meshes/middle2.STL" />
      </geometry>
      <material
        name="">
        <color
          rgba="0.79216 0.81961 0.93333 1" />
      </material>
    </visual>
    <collision>
      <origin
        xyz="0 0 0"
        rpy="0 0 0" />
      <geometry>
        <mesh
          filename="package://hand/meshes/middle2.STL" />
      </geometry>
    </collision>
  </link>
  <joint
    name="middle_12"
    type="revolute">
    <origin
      xyz="0.035822 0 0"
      rpy="0 0 0" />
    <parent
      link="middle1" />
    <child
      link="middle2" />
    <axis
      xyz="0 0 1" />
    <limit
      lower="-1.57"
      upper="1.57"
      effort="0"
      velocity="0" />
  </joint>
  <link
    name="ring1">
    <inertial>
      <origin
        xyz="0.015715 -0.0016164 1.482E-06"
        rpy="0 0 0" />
      <mass
        value="0.005044" />
      <inertia
        ixx="2.0628E-07"
        ixy="2.8006E-09"
        ixz="-6.5184E-12"
        iyy="7.4369E-07"
        iyz="6.0329E-11"
        izz="8.1295E-07" />
    </inertial>
    <visual>
      <origin
        xyz="0 0 0"
        rpy="0 0 0" />
      <geometry>
        <mesh
          filename="package://hand/meshes/ring1.STL" />
      </geometry>
      <material
        name="">
        <color
          rgba="0.79216 0.81961 0.93333 1" />
      </material>
    </visual>
    <collision>
      <origin
        xyz="0 0 0"
        rpy="0 0 0" />
      <geometry>
        <mesh
          filename="package://hand/meshes/ring1.STL" />
      </geometry>
    </collision>
  </link>
  <joint
    name="palm_ring1"
    type="revolute">
    <origin
      xyz="-0.012095 -0.0020884 0.12429"
      rpy="-3.1416 -1.5184 3.1416" />
    <parent
      link="palm" />
    <child
      link="ring1" />
    <axis
      xyz="0 0.00091329 1" />
    <limit
      lower="-1.57"
      upper="1.57"
      effort="0"
      velocity="0" />
  </joint>
  <link
    name="ring2">
    <inertial>
      <origin
        xyz="0.020136 -0.0021343 2.8584E-06"
        rpy="0 0 0" />
      <mass
        value="0.0042224" />
      <inertia
        ixx="8.371E-08"
        ixy="-4.4514E-08"
        ixz="1.1386E-10"
        iyy="6.7979E-07"
        iyz="3.0518E-11"
        izz="6.8975E-07" />
    </inertial>
    <visual>
      <origin
        xyz="0 0 0"
        rpy="0 0 0" />
      <geometry>
        <mesh
          filename="package://hand/meshes/ring2.STL" />
      </geometry>
      <material
        name="">
        <color
          rgba="0.79216 0.81961 0.93333 1" />
      </material>
    </visual>
    <collision>
      <origin
        xyz="0 0 0"
        rpy="0 0 0" />
      <geometry>
        <mesh
          filename="package://hand/meshes/ring2.STL" />
      </geometry>
    </collision>
  </link>
  <joint
    name="ring_12"
    type="revolute">
    <origin
      xyz="0.036089 0 0"
      rpy="0 0 0" />
    <parent
      link="ring1" />
    <child
      link="ring2" />
    <axis
      xyz="0 0.00091329 1" />
    <limit
      lower="-1.57"
      upper="1.57"
      effort="0"
      velocity="0" />
  </joint>
  <link
    name="little1">
    <inertial>
      <origin
        xyz="0.015515 -0.0020772 3.7962E-06"
        rpy="0 0 0" />
      <mass
        value="0.004837" />
      <inertia
        ixx="1.9887E-07"
        ixy="1.9574E-08"
        ixz="-3.2281E-11"
        iyy="6.9992E-07"
        iyz="1.1589E-10"
        izz="7.6407E-07" />
    </inertial>
    <visual>
      <origin
        xyz="0 0 0"
        rpy="0 0 0" />
      <geometry>
        <mesh
          filename="package://hand/meshes/little1.STL" />
      </geometry>
      <material
        name="">
        <color
          rgba="0.79216 0.81961 0.93333 1" />
      </material>
    </visual>
    <collision>
      <origin
        xyz="0 0 0"
        rpy="0 0 0" />
      <geometry>
        <mesh
          filename="package://hand/meshes/little1.STL" />
      </geometry>
    </collision>
  </link>
  <joint
    name="palm_little1"
    type="revolute">
    <origin
      xyz="-0.031086 -0.0020623 0.1228"
      rpy="3.1416 -1.4661 3.1416" />
    <parent
      link="palm" />
    <child
      link="little1" />
    <axis
      xyz="0 0.0018242 1" />
    <limit
      lower="-1.57"
      upper="1.57"
      effort="0"
      velocity="0" />
  </joint>
  <link
    name="little2">
    <inertial>
      <origin
        xyz="0.016676 -0.0028045 -3.7906E-05"
        rpy="0 0 0" />
      <mass
        value="0.0035295" />
      <inertia
        ixx="7.2229E-08"
        ixy="-4.2588E-08"
        ixz="4.4869E-10"
        iyy="4.1119E-07"
        iyz="3.255E-11"
        izz="4.1902E-07" />
    </inertial>
    <visual>
      <origin
        xyz="0 0 0"
        rpy="0 0 0" />
      <geometry>
        <mesh
          filename="package://hand/meshes/little2.STL" />
      </geometry>
      <material
        name="">
        <color
          rgba="0.79216 0.81961 0.93333 1" />
      </material>
    </visual>
    <collision>
      <origin
        xyz="0 0 0"
        rpy="0 0 0" />
      <geometry>
        <mesh
          filename="package://hand/meshes/little2.STL" />
      </geometry>
    </collision>
  </link>
  <joint
    name="little_12"
    type="revolute">
    <origin
      xyz="0.035646 0 0"
      rpy="0 0 0" />
    <parent
      link="little1" />
    <child
      link="little2" />
    <axis
      xyz="0 0.0018242 1" />
    <limit
      lower="-1.57"
      upper="1.57"
      effort="0"
      velocity="0" />
  </joint>
</robot>
